[2025-08-02T20:10:43.695+0000] {local_task_job_runner.py:120} INFO - ::group::Pre task execution logs
[2025-08-02T20:10:43.723+0000] {taskinstance.py:2076} INFO - Dependencies all met for dep_context=non-requeueable deps ti=<TaskInstance: gcs_move_landing_to_raw_v1.move_users_file manual__2025-08-02T20:10:39.170346+00:00 [queued]>
[2025-08-02T20:10:43.736+0000] {taskinstance.py:2076} INFO - Dependencies all met for dep_context=requeueable deps ti=<TaskInstance: gcs_move_landing_to_raw_v1.move_users_file manual__2025-08-02T20:10:39.170346+00:00 [queued]>
[2025-08-02T20:10:43.746+0000] {taskinstance.py:2306} INFO - Starting attempt 1 of 1
[2025-08-02T20:10:43.766+0000] {taskinstance.py:2330} INFO - Executing <Task(GCSToGCSOperator): move_users_file> on 2025-08-02 20:10:39.170346+00:00
[2025-08-02T20:10:43.784+0000] {warnings.py:112} WARNING - /home/***/.local/lib/python3.12/site-packages/***/task/task_runner/standard_task_runner.py:61: DeprecationWarning: This process (pid=343) is multi-threaded, use of fork() may lead to deadlocks in the child.
  pid = os.fork()

[2025-08-02T20:10:43.787+0000] {standard_task_runner.py:90} INFO - Running: ['***', 'tasks', 'run', 'gcs_move_landing_to_raw_v1', 'move_users_file', 'manual__2025-08-02T20:10:39.170346+00:00', '--job-id', '30', '--raw', '--subdir', 'DAGS_FOLDER/gcs_load_dag.py', '--cfg-path', '/tmp/tmpfj117s75']
[2025-08-02T20:10:43.793+0000] {standard_task_runner.py:63} INFO - Started process 349 to run task
[2025-08-02T20:10:43.793+0000] {standard_task_runner.py:91} INFO - Job 30: Subtask move_users_file
[2025-08-02T20:10:43.895+0000] {task_command.py:426} INFO - Running <TaskInstance: gcs_move_landing_to_raw_v1.move_users_file manual__2025-08-02T20:10:39.170346+00:00 [running]> on host 06d424bf0ee1
[2025-08-02T20:10:44.048+0000] {taskinstance.py:2648} INFO - Exporting env vars: AIRFLOW_CTX_DAG_OWNER='***' AIRFLOW_CTX_DAG_ID='gcs_move_landing_to_raw_v1' AIRFLOW_CTX_TASK_ID='move_users_file' AIRFLOW_CTX_EXECUTION_DATE='2025-08-02T20:10:39.170346+00:00' AIRFLOW_CTX_TRY_NUMBER='1' AIRFLOW_CTX_DAG_RUN_ID='manual__2025-08-02T20:10:39.170346+00:00'
[2025-08-02T20:10:44.052+0000] {taskinstance.py:430} INFO - ::endgroup::
[2025-08-02T20:10:44.065+0000] {connection.py:274} WARNING - Connection schemes (type: google_cloud_platform) shall not contain '_' according to RFC3986.
[2025-08-02T20:10:44.069+0000] {base.py:84} INFO - Using connection ID 'google_cloud_default' for task execution.
[2025-08-02T20:10:44.071+0000] {taskinstance.py:441} INFO - ::group::Post task execution logs
[2025-08-02T20:10:44.088+0000] {taskinstance.py:2905} ERROR - Task failed with exception
Traceback (most recent call last):
  File "/home/airflow/.local/lib/python3.12/site-packages/airflow/models/taskinstance.py", line 465, in _execute_task
    result = _execute_callable(context=context, **execute_callable_kwargs)
             ^^^^^^^^^^^^^^^^^^^^^^^^^^^^^^^^^^^^^^^^^^^^^^^^^^^^^^^^^^^^^
  File "/home/airflow/.local/lib/python3.12/site-packages/airflow/models/taskinstance.py", line 432, in _execute_callable
    return execute_callable(context=context, **execute_callable_kwargs)
           ^^^^^^^^^^^^^^^^^^^^^^^^^^^^^^^^^^^^^^^^^^^^^^^^^^^^^^^^^^^^
  File "/home/airflow/.local/lib/python3.12/site-packages/airflow/models/baseoperator.py", line 401, in wrapper
    return func(self, *args, **kwargs)
           ^^^^^^^^^^^^^^^^^^^^^^^^^^^
  File "/home/airflow/.local/lib/python3.12/site-packages/airflow/providers/google/cloud/transfers/gcs_to_gcs.py", line 281, in execute
    self._copy_source_without_wildcard(hook=hook, prefix=prefix)
  File "/home/airflow/.local/lib/python3.12/site-packages/airflow/providers/google/cloud/transfers/gcs_to_gcs.py", line 388, in _copy_source_without_wildcard
    objects = hook.list(
              ^^^^^^^^^^
  File "/home/airflow/.local/lib/python3.12/site-packages/airflow/providers/google/cloud/hooks/gcs.py", line 768, in list
    self._list(
  File "/home/airflow/.local/lib/python3.12/site-packages/airflow/providers/google/cloud/hooks/gcs.py", line 804, in _list
    client = self.get_conn()
             ^^^^^^^^^^^^^^^
  File "/home/airflow/.local/lib/python3.12/site-packages/airflow/providers/google/cloud/hooks/gcs.py", line 173, in get_conn
    credentials=self.get_credentials(), client_info=CLIENT_INFO, project=self.project_id
                ^^^^^^^^^^^^^^^^^^^^^^
  File "/home/airflow/.local/lib/python3.12/site-packages/airflow/providers/google/common/hooks/base_google.py", line 332, in get_credentials
    credentials, _ = self.get_credentials_and_project_id()
                     ^^^^^^^^^^^^^^^^^^^^^^^^^^^^^^^^^^^^^
  File "/home/airflow/.local/lib/python3.12/site-packages/airflow/providers/google/common/hooks/base_google.py", line 308, in get_credentials_and_project_id
    credentials, project_id = get_credentials_and_project_id(
                              ^^^^^^^^^^^^^^^^^^^^^^^^^^^^^^^
  File "/home/airflow/.local/lib/python3.12/site-packages/airflow/providers/google/cloud/utils/credentials_provider.py", line 371, in get_credentials_and_project_id
    return _CredentialProvider(*args, **kwargs).get_credentials_and_project()
           ^^^^^^^^^^^^^^^^^^^^^^^^^^^^^^^^^^^^^^^^^^^^^^^^^^^^^^^^^^^^^^^^^^
  File "/home/airflow/.local/lib/python3.12/site-packages/airflow/providers/google/cloud/utils/credentials_provider.py", line 245, in get_credentials_and_project
    credentials, project_id = self._get_credentials_using_key_path()
                              ^^^^^^^^^^^^^^^^^^^^^^^^^^^^^^^^^^^^^^
  File "/home/airflow/.local/lib/python3.12/site-packages/airflow/providers/google/cloud/utils/credentials_provider.py", line 292, in _get_credentials_using_key_path
    raise AirflowException("Unrecognised extension for key file.")
airflow.exceptions.AirflowException: Unrecognised extension for key file.
[2025-08-02T20:10:44.096+0000] {taskinstance.py:1206} INFO - Marking task as FAILED. dag_id=gcs_move_landing_to_raw_v1, task_id=move_users_file, run_id=manual__2025-08-02T20:10:39.170346+00:00, execution_date=20250802T201039, start_date=20250802T201043, end_date=20250802T201044
[2025-08-02T20:10:44.119+0000] {standard_task_runner.py:110} ERROR - Failed to execute job 30 for task move_users_file (Unrecognised extension for key file.; 349)
[2025-08-02T20:10:44.170+0000] {local_task_job_runner.py:240} INFO - Task exited with return code 1
[2025-08-02T20:10:44.186+0000] {local_task_job_runner.py:222} INFO - ::endgroup::
