[2025-08-10T18:21:15.954+0000] {local_task_job_runner.py:120} INFO - ::group::Pre task execution logs
[2025-08-10T18:21:16.003+0000] {taskinstance.py:2076} INFO - Dependencies all met for dep_context=non-requeueable deps ti=<TaskInstance: dbt_run_pipeline_v1.dbt_run manual__2025-08-10T18:21:14.039423+00:00 [queued]>
[2025-08-10T18:21:16.017+0000] {taskinstance.py:2076} INFO - Dependencies all met for dep_context=requeueable deps ti=<TaskInstance: dbt_run_pipeline_v1.dbt_run manual__2025-08-10T18:21:14.039423+00:00 [queued]>
[2025-08-10T18:21:16.027+0000] {taskinstance.py:2306} INFO - Starting attempt 1 of 1
[2025-08-10T18:21:16.051+0000] {taskinstance.py:2330} INFO - Executing <Task(BashOperator): dbt_run> on 2025-08-10 18:21:14.039423+00:00
[2025-08-10T18:21:16.065+0000] {warnings.py:112} WARNING - /home/***/.local/lib/python3.12/site-packages/***/task/task_runner/standard_task_runner.py:61: DeprecationWarning: This process (pid=305) is multi-threaded, use of fork() may lead to deadlocks in the child.
  pid = os.fork()

[2025-08-10T18:21:16.069+0000] {standard_task_runner.py:63} INFO - Started process 306 to run task
[2025-08-10T18:21:16.068+0000] {standard_task_runner.py:90} INFO - Running: ['***', 'tasks', 'run', 'dbt_run_pipeline_v1', 'dbt_run', 'manual__2025-08-10T18:21:14.039423+00:00', '--job-id', '4', '--raw', '--subdir', 'DAGS_FOLDER/dbt_run_pipeline_v1.py', '--cfg-path', '/tmp/tmpkbumdce2']
[2025-08-10T18:21:16.070+0000] {standard_task_runner.py:91} INFO - Job 4: Subtask dbt_run
[2025-08-10T18:21:16.170+0000] {task_command.py:426} INFO - Running <TaskInstance: dbt_run_pipeline_v1.dbt_run manual__2025-08-10T18:21:14.039423+00:00 [running]> on host e94eaa51f89a
[2025-08-10T18:21:16.349+0000] {taskinstance.py:2648} INFO - Exporting env vars: AIRFLOW_CTX_DAG_OWNER='***' AIRFLOW_CTX_DAG_ID='dbt_run_pipeline_v1' AIRFLOW_CTX_TASK_ID='dbt_run' AIRFLOW_CTX_EXECUTION_DATE='2025-08-10T18:21:14.039423+00:00' AIRFLOW_CTX_TRY_NUMBER='1' AIRFLOW_CTX_DAG_RUN_ID='manual__2025-08-10T18:21:14.039423+00:00'
[2025-08-10T18:21:16.353+0000] {taskinstance.py:430} INFO - ::endgroup::
[2025-08-10T18:21:16.380+0000] {subprocess.py:63} INFO - Tmp dir root location: /tmp
[2025-08-10T18:21:16.381+0000] {subprocess.py:75} INFO - Running command: ['/usr/bin/bash', '-c', 'dbt run']
[2025-08-10T18:21:16.409+0000] {subprocess.py:86} INFO - Output:
[2025-08-10T18:21:19.755+0000] {subprocess.py:93} INFO - [0m18:21:19  Running with dbt=1.10.7
[2025-08-10T18:21:24.188+0000] {subprocess.py:93} INFO - [0m18:21:24  Registered adapter: bigquery=1.10.1
[2025-08-10T18:21:25.979+0000] {subprocess.py:93} INFO - [0m18:21:25  Found 8 models, 4 sources, 496 macros
[2025-08-10T18:21:25.986+0000] {subprocess.py:93} INFO - [0m18:21:25
[2025-08-10T18:21:25.988+0000] {subprocess.py:93} INFO - [0m18:21:25  Concurrency: 1 threads (target='dev')
[2025-08-10T18:21:25.989+0000] {subprocess.py:93} INFO - [0m18:21:25
[2025-08-10T18:21:28.089+0000] {subprocess.py:93} INFO - [0m18:21:28  1 of 8 START sql view model transaction_analytics.stg_cards .................... [RUN]
[2025-08-10T18:21:29.948+0000] {subprocess.py:93} INFO - [0m18:21:29  1 of 8 OK created sql view model transaction_analytics.stg_cards ............... [[32mCREATE VIEW (0 processed)[0m in 1.85s]
[2025-08-10T18:21:29.957+0000] {subprocess.py:93} INFO - [0m18:21:29  2 of 8 START sql view model transaction_analytics.stg_mcc ...................... [RUN]
[2025-08-10T18:21:31.438+0000] {subprocess.py:93} INFO - [0m18:21:31  2 of 8 OK created sql view model transaction_analytics.stg_mcc ................. [[32mCREATE VIEW (0 processed)[0m in 1.47s]
[2025-08-10T18:21:31.446+0000] {subprocess.py:93} INFO - [0m18:21:31  3 of 8 START sql view model transaction_analytics.stg_transactions ............. [RUN]
[2025-08-10T18:21:32.897+0000] {subprocess.py:93} INFO - [0m18:21:32  3 of 8 OK created sql view model transaction_analytics.stg_transactions ........ [[32mCREATE VIEW (0 processed)[0m in 1.44s]
[2025-08-10T18:21:32.903+0000] {subprocess.py:93} INFO - [0m18:21:32  4 of 8 START sql view model transaction_analytics.stg_users .................... [RUN]
[2025-08-10T18:21:34.961+0000] {subprocess.py:93} INFO - [0m18:21:34  4 of 8 OK created sql view model transaction_analytics.stg_users ............... [[32mCREATE VIEW (0 processed)[0m in 2.05s]
[2025-08-10T18:21:34.967+0000] {subprocess.py:93} INFO - [0m18:21:34  5 of 8 START sql view model transaction_analytics.dim_cards .................... [RUN]
[2025-08-10T18:21:37.318+0000] {subprocess.py:93} INFO - [0m18:21:37  5 of 8 OK created sql view model transaction_analytics.dim_cards ............... [[32mCREATE VIEW (0 processed)[0m in 2.35s]
[2025-08-10T18:21:37.327+0000] {subprocess.py:93} INFO - [0m18:21:37  6 of 8 START sql view model transaction_analytics.dim_mcc_codes ................ [RUN]
[2025-08-10T18:21:39.405+0000] {subprocess.py:93} INFO - [0m18:21:39  6 of 8 OK created sql view model transaction_analytics.dim_mcc_codes ........... [[32mCREATE VIEW (0 processed)[0m in 2.07s]
[2025-08-10T18:21:39.412+0000] {subprocess.py:93} INFO - [0m18:21:39  7 of 8 START sql view model transaction_analytics.dim_users .................... [RUN]
[2025-08-10T18:21:41.853+0000] {subprocess.py:93} INFO - [0m18:21:41  7 of 8 OK created sql view model transaction_analytics.dim_users ............... [[32mCREATE VIEW (0 processed)[0m in 2.43s]
[2025-08-10T18:21:41.864+0000] {subprocess.py:93} INFO - [0m18:21:41  8 of 8 START sql view model transaction_analytics.fct_transactions ............. [RUN]
[2025-08-10T18:21:43.892+0000] {subprocess.py:93} INFO - [0m18:21:43  BigQuery adapter: https://console.cloud.google.com/bigquery?project=dataverse-360&j=bq:europe-west2:381ba66d-a920-4610-849d-5c7455c89684&page=queryresults
[2025-08-10T18:21:43.912+0000] {subprocess.py:93} INFO - [0m18:21:43  8 of 8 ERROR creating sql view model transaction_analytics.fct_transactions .... [[31mERROR[0m in 2.04s]
[2025-08-10T18:21:43.990+0000] {subprocess.py:93} INFO - [0m18:21:43
[2025-08-10T18:21:43.992+0000] {subprocess.py:93} INFO - [0m18:21:43  Finished running 8 view models in 0 hours 0 minutes and 18.00 seconds (18.00s).
[2025-08-10T18:21:44.100+0000] {subprocess.py:93} INFO - [0m18:21:44
[2025-08-10T18:21:44.102+0000] {subprocess.py:93} INFO - [0m18:21:44  [31mCompleted with 1 error, 0 partial successes, and 0 warnings:[0m
[2025-08-10T18:21:44.104+0000] {subprocess.py:93} INFO - [0m18:21:44
[2025-08-10T18:21:44.105+0000] {subprocess.py:93} INFO - [0m18:21:44  [31mFailure in model fct_transactions (models/marts/fct_transactions.sql)[0m
[2025-08-10T18:21:44.107+0000] {subprocess.py:93} INFO - [0m18:21:44    Database Error in model fct_transactions (models/marts/fct_transactions.sql)
[2025-08-10T18:21:44.108+0000] {subprocess.py:93} INFO -   Column name card_id is ambiguous at [10:1]
[2025-08-10T18:21:44.108+0000] {subprocess.py:93} INFO -   compiled code at target/run/transaction_analytics/models/marts/fct_transactions.sql
[2025-08-10T18:21:44.109+0000] {subprocess.py:93} INFO - [0m18:21:44
[2025-08-10T18:21:44.110+0000] {subprocess.py:93} INFO - [0m18:21:44    compiled code at target/compiled/transaction_analytics/models/marts/fct_transactions.sql
[2025-08-10T18:21:44.113+0000] {subprocess.py:93} INFO - [0m18:21:44
[2025-08-10T18:21:44.114+0000] {subprocess.py:93} INFO - [0m18:21:44  Done. PASS=7 WARN=0 ERROR=1 SKIP=0 NO-OP=0 TOTAL=8
[2025-08-10T18:21:47.294+0000] {subprocess.py:97} INFO - Command exited with return code 1
[2025-08-10T18:21:47.295+0000] {taskinstance.py:441} INFO - ::group::Post task execution logs
[2025-08-10T18:21:47.315+0000] {taskinstance.py:2905} ERROR - Task failed with exception
Traceback (most recent call last):
  File "/home/airflow/.local/lib/python3.12/site-packages/airflow/models/taskinstance.py", line 465, in _execute_task
    result = _execute_callable(context=context, **execute_callable_kwargs)
             ^^^^^^^^^^^^^^^^^^^^^^^^^^^^^^^^^^^^^^^^^^^^^^^^^^^^^^^^^^^^^
  File "/home/airflow/.local/lib/python3.12/site-packages/airflow/models/taskinstance.py", line 432, in _execute_callable
    return execute_callable(context=context, **execute_callable_kwargs)
           ^^^^^^^^^^^^^^^^^^^^^^^^^^^^^^^^^^^^^^^^^^^^^^^^^^^^^^^^^^^^
  File "/home/airflow/.local/lib/python3.12/site-packages/airflow/models/baseoperator.py", line 401, in wrapper
    return func(self, *args, **kwargs)
           ^^^^^^^^^^^^^^^^^^^^^^^^^^^
  File "/home/airflow/.local/lib/python3.12/site-packages/airflow/operators/bash.py", line 243, in execute
    raise AirflowException(
airflow.exceptions.AirflowException: Bash command failed. The command returned a non-zero exit code 1.
[2025-08-10T18:21:47.321+0000] {taskinstance.py:1206} INFO - Marking task as FAILED. dag_id=dbt_run_pipeline_v1, task_id=dbt_run, run_id=manual__2025-08-10T18:21:14.039423+00:00, execution_date=20250810T182114, start_date=20250810T182116, end_date=20250810T182147
[2025-08-10T18:21:47.355+0000] {standard_task_runner.py:110} ERROR - Failed to execute job 4 for task dbt_run (Bash command failed. The command returned a non-zero exit code 1.; 306)
[2025-08-10T18:21:47.386+0000] {local_task_job_runner.py:240} INFO - Task exited with return code 1
[2025-08-10T18:21:47.411+0000] {taskinstance.py:3503} INFO - 0 downstream tasks scheduled from follow-on schedule check
[2025-08-10T18:21:47.424+0000] {local_task_job_runner.py:222} INFO - ::endgroup::
