[2025-08-12T02:32:49.647+0000] {local_task_job_runner.py:120} INFO - ::group::Pre task execution logs
[2025-08-12T02:32:49.711+0000] {taskinstance.py:2076} INFO - Dependencies all met for dep_context=non-requeueable deps ti=<TaskInstance: dbt_run_pipeline_v1.dbt_run manual__2025-08-12T02:32:46.408506+00:00 [queued]>
[2025-08-12T02:32:49.727+0000] {taskinstance.py:2076} INFO - Dependencies all met for dep_context=requeueable deps ti=<TaskInstance: dbt_run_pipeline_v1.dbt_run manual__2025-08-12T02:32:46.408506+00:00 [queued]>
[2025-08-12T02:32:49.730+0000] {taskinstance.py:2306} INFO - Starting attempt 1 of 1
[2025-08-12T02:32:49.760+0000] {taskinstance.py:2330} INFO - Executing <Task(BashOperator): dbt_run> on 2025-08-12 02:32:46.408506+00:00
[2025-08-12T02:32:49.774+0000] {warnings.py:112} WARNING - /home/***/.local/lib/python3.12/site-packages/***/task/task_runner/standard_task_runner.py:61: DeprecationWarning: This process (pid=1380) is multi-threaded, use of fork() may lead to deadlocks in the child.
  pid = os.fork()

[2025-08-12T02:32:49.779+0000] {standard_task_runner.py:90} INFO - Running: ['***', 'tasks', 'run', 'dbt_run_pipeline_v1', 'dbt_run', 'manual__2025-08-12T02:32:46.408506+00:00', '--job-id', '11', '--raw', '--subdir', 'DAGS_FOLDER/dbt_run_pipeline_v1.py', '--cfg-path', '/tmp/tmp7ygfos5x']
[2025-08-12T02:32:49.780+0000] {standard_task_runner.py:63} INFO - Started process 1381 to run task
[2025-08-12T02:32:49.781+0000] {standard_task_runner.py:91} INFO - Job 11: Subtask dbt_run
[2025-08-12T02:32:49.896+0000] {task_command.py:426} INFO - Running <TaskInstance: dbt_run_pipeline_v1.dbt_run manual__2025-08-12T02:32:46.408506+00:00 [running]> on host ef2de7cf7633
[2025-08-12T02:32:50.079+0000] {taskinstance.py:2648} INFO - Exporting env vars: AIRFLOW_CTX_DAG_OWNER='***' AIRFLOW_CTX_DAG_ID='dbt_run_pipeline_v1' AIRFLOW_CTX_TASK_ID='dbt_run' AIRFLOW_CTX_EXECUTION_DATE='2025-08-12T02:32:46.408506+00:00' AIRFLOW_CTX_TRY_NUMBER='1' AIRFLOW_CTX_DAG_RUN_ID='manual__2025-08-12T02:32:46.408506+00:00'
[2025-08-12T02:32:50.081+0000] {taskinstance.py:430} INFO - ::endgroup::
[2025-08-12T02:32:50.121+0000] {subprocess.py:63} INFO - Tmp dir root location: /tmp
[2025-08-12T02:32:50.122+0000] {subprocess.py:75} INFO - Running command: ['/usr/bin/bash', '-c', 'dbt run']
[2025-08-12T02:32:50.145+0000] {subprocess.py:86} INFO - Output:
[2025-08-12T02:32:54.299+0000] {subprocess.py:93} INFO - [0m02:32:54  Running with dbt=1.10.7
[2025-08-12T02:33:00.921+0000] {subprocess.py:93} INFO - [0m02:33:00  Registered adapter: bigquery=1.10.1
[2025-08-12T02:33:02.867+0000] {subprocess.py:93} INFO - [0m02:33:02  Found 8 models, 4 sources, 496 macros
[2025-08-12T02:33:02.873+0000] {subprocess.py:93} INFO - [0m02:33:02
[2025-08-12T02:33:02.875+0000] {subprocess.py:93} INFO - [0m02:33:02  Concurrency: 1 threads (target='dev')
[2025-08-12T02:33:02.877+0000] {subprocess.py:93} INFO - [0m02:33:02
[2025-08-12T02:33:05.551+0000] {subprocess.py:93} INFO - [0m02:33:05  1 of 8 START sql view model transaction_analytics.stg_cards .................... [RUN]
[2025-08-12T02:33:08.035+0000] {subprocess.py:93} INFO - [0m02:33:08  1 of 8 OK created sql view model transaction_analytics.stg_cards ............... [[32mCREATE VIEW (0 processed)[0m in 2.47s]
[2025-08-12T02:33:08.041+0000] {subprocess.py:93} INFO - [0m02:33:08  2 of 8 START sql view model transaction_analytics.stg_mcc ...................... [RUN]
[2025-08-12T02:33:09.952+0000] {subprocess.py:93} INFO - [0m02:33:09  2 of 8 OK created sql view model transaction_analytics.stg_mcc ................. [[32mCREATE VIEW (0 processed)[0m in 1.90s]
[2025-08-12T02:33:09.959+0000] {subprocess.py:93} INFO - [0m02:33:09  3 of 8 START sql view model transaction_analytics.stg_transactions ............. [RUN]
[2025-08-12T02:33:12.278+0000] {subprocess.py:93} INFO - [0m02:33:12  3 of 8 OK created sql view model transaction_analytics.stg_transactions ........ [[32mCREATE VIEW (0 processed)[0m in 2.31s]
[2025-08-12T02:33:12.285+0000] {subprocess.py:93} INFO - [0m02:33:12  4 of 8 START sql view model transaction_analytics.stg_users .................... [RUN]
[2025-08-12T02:33:14.539+0000] {subprocess.py:93} INFO - [0m02:33:14  4 of 8 OK created sql view model transaction_analytics.stg_users ............... [[32mCREATE VIEW (0 processed)[0m in 2.25s]
[2025-08-12T02:33:14.546+0000] {subprocess.py:93} INFO - [0m02:33:14  5 of 8 START sql view model transaction_analytics.dim_cards .................... [RUN]
[2025-08-12T02:33:16.383+0000] {subprocess.py:93} INFO - [0m02:33:16  BigQuery adapter: https://console.cloud.google.com/bigquery?project=dataverse-360&j=bq:europe-west2:054e9652-b11f-4157-8d9b-e8117bab6784&page=queryresults
[2025-08-12T02:33:16.414+0000] {subprocess.py:93} INFO - [0m02:33:16  5 of 8 ERROR creating sql view model transaction_analytics.dim_cards ........... [[31mERROR[0m in 1.86s]
[2025-08-12T02:33:16.424+0000] {subprocess.py:93} INFO - [0m02:33:16  6 of 8 START sql view model transaction_analytics.dim_mcc_codes ................ [RUN]
[2025-08-12T02:33:18.849+0000] {subprocess.py:93} INFO - [0m02:33:18  6 of 8 OK created sql view model transaction_analytics.dim_mcc_codes ........... [[32mCREATE VIEW (0 processed)[0m in 2.42s]
[2025-08-12T02:33:18.865+0000] {subprocess.py:93} INFO - [0m02:33:18  7 of 8 START sql view model transaction_analytics.dim_users .................... [RUN]
[2025-08-12T02:33:21.110+0000] {subprocess.py:93} INFO - [0m02:33:21  7 of 8 OK created sql view model transaction_analytics.dim_users ............... [[32mCREATE VIEW (0 processed)[0m in 2.24s]
[2025-08-12T02:33:21.118+0000] {subprocess.py:93} INFO - [0m02:33:21  8 of 8 SKIP relation transaction_analytics.fct_transactions .................... [[33mSKIP[0m]
[2025-08-12T02:33:21.195+0000] {subprocess.py:93} INFO - [0m02:33:21
[2025-08-12T02:33:21.197+0000] {subprocess.py:93} INFO - [0m02:33:21  Finished running 8 view models in 0 hours 0 minutes and 18.32 seconds (18.32s).
[2025-08-12T02:33:21.398+0000] {subprocess.py:93} INFO - [0m02:33:21
[2025-08-12T02:33:21.401+0000] {subprocess.py:93} INFO - [0m02:33:21  [31mCompleted with 1 error, 0 partial successes, and 0 warnings:[0m
[2025-08-12T02:33:21.402+0000] {subprocess.py:93} INFO - [0m02:33:21
[2025-08-12T02:33:21.404+0000] {subprocess.py:93} INFO - [0m02:33:21  [31mFailure in model dim_cards (models/marts/dim_cards.sql)[0m
[2025-08-12T02:33:21.405+0000] {subprocess.py:93} INFO - [0m02:33:21    Database Error in model dim_cards (models/marts/dim_cards.sql)
[2025-08-12T02:33:21.406+0000] {subprocess.py:93} INFO -   Unrecognized name: expires_numeric at [13:1]
[2025-08-12T02:33:21.406+0000] {subprocess.py:93} INFO -   compiled code at target/run/transaction_analytics/models/marts/dim_cards.sql
[2025-08-12T02:33:21.407+0000] {subprocess.py:93} INFO - [0m02:33:21
[2025-08-12T02:33:21.408+0000] {subprocess.py:93} INFO - [0m02:33:21    compiled code at target/compiled/transaction_analytics/models/marts/dim_cards.sql
[2025-08-12T02:33:21.410+0000] {subprocess.py:93} INFO - [0m02:33:21
[2025-08-12T02:33:21.412+0000] {subprocess.py:93} INFO - [0m02:33:21  Done. PASS=6 WARN=0 ERROR=1 SKIP=1 NO-OP=0 TOTAL=8
[2025-08-12T02:33:24.159+0000] {subprocess.py:97} INFO - Command exited with return code 1
[2025-08-12T02:33:24.160+0000] {taskinstance.py:441} INFO - ::group::Post task execution logs
[2025-08-12T02:33:24.185+0000] {taskinstance.py:2905} ERROR - Task failed with exception
Traceback (most recent call last):
  File "/home/airflow/.local/lib/python3.12/site-packages/airflow/models/taskinstance.py", line 465, in _execute_task
    result = _execute_callable(context=context, **execute_callable_kwargs)
             ^^^^^^^^^^^^^^^^^^^^^^^^^^^^^^^^^^^^^^^^^^^^^^^^^^^^^^^^^^^^^
  File "/home/airflow/.local/lib/python3.12/site-packages/airflow/models/taskinstance.py", line 432, in _execute_callable
    return execute_callable(context=context, **execute_callable_kwargs)
           ^^^^^^^^^^^^^^^^^^^^^^^^^^^^^^^^^^^^^^^^^^^^^^^^^^^^^^^^^^^^
  File "/home/airflow/.local/lib/python3.12/site-packages/airflow/models/baseoperator.py", line 401, in wrapper
    return func(self, *args, **kwargs)
           ^^^^^^^^^^^^^^^^^^^^^^^^^^^
  File "/home/airflow/.local/lib/python3.12/site-packages/airflow/operators/bash.py", line 243, in execute
    raise AirflowException(
airflow.exceptions.AirflowException: Bash command failed. The command returned a non-zero exit code 1.
[2025-08-12T02:33:24.202+0000] {taskinstance.py:1206} INFO - Marking task as FAILED. dag_id=dbt_run_pipeline_v1, task_id=dbt_run, run_id=manual__2025-08-12T02:32:46.408506+00:00, execution_date=20250812T023246, start_date=20250812T023249, end_date=20250812T023324
[2025-08-12T02:33:24.241+0000] {standard_task_runner.py:110} ERROR - Failed to execute job 11 for task dbt_run (Bash command failed. The command returned a non-zero exit code 1.; 1381)
[2025-08-12T02:33:24.294+0000] {local_task_job_runner.py:240} INFO - Task exited with return code 1
[2025-08-12T02:33:24.321+0000] {taskinstance.py:3503} INFO - 0 downstream tasks scheduled from follow-on schedule check
[2025-08-12T02:33:24.333+0000] {local_task_job_runner.py:222} INFO - ::endgroup::
