[2025-08-10T18:19:32.922+0000] {local_task_job_runner.py:120} INFO - ::group::Pre task execution logs
[2025-08-10T18:19:32.965+0000] {taskinstance.py:2076} INFO - Dependencies all met for dep_context=non-requeueable deps ti=<TaskInstance: dbt_run_pipeline_v1.dbt_run manual__2025-08-10T18:19:30.844351+00:00 [queued]>
[2025-08-10T18:19:32.979+0000] {taskinstance.py:2076} INFO - Dependencies all met for dep_context=requeueable deps ti=<TaskInstance: dbt_run_pipeline_v1.dbt_run manual__2025-08-10T18:19:30.844351+00:00 [queued]>
[2025-08-10T18:19:32.988+0000] {taskinstance.py:2306} INFO - Starting attempt 1 of 1
[2025-08-10T18:19:33.013+0000] {taskinstance.py:2330} INFO - Executing <Task(BashOperator): dbt_run> on 2025-08-10 18:19:30.844351+00:00
[2025-08-10T18:19:33.025+0000] {warnings.py:112} WARNING - /home/***/.local/lib/python3.12/site-packages/***/task/task_runner/standard_task_runner.py:61: DeprecationWarning: This process (pid=241) is multi-threaded, use of fork() may lead to deadlocks in the child.
  pid = os.fork()

[2025-08-10T18:19:33.029+0000] {standard_task_runner.py:90} INFO - Running: ['***', 'tasks', 'run', 'dbt_run_pipeline_v1', 'dbt_run', 'manual__2025-08-10T18:19:30.844351+00:00', '--job-id', '3', '--raw', '--subdir', 'DAGS_FOLDER/dbt_run_pipeline_v1.py', '--cfg-path', '/tmp/tmp08a6mpef']
[2025-08-10T18:19:33.030+0000] {standard_task_runner.py:63} INFO - Started process 242 to run task
[2025-08-10T18:19:33.031+0000] {standard_task_runner.py:91} INFO - Job 3: Subtask dbt_run
[2025-08-10T18:19:33.159+0000] {task_command.py:426} INFO - Running <TaskInstance: dbt_run_pipeline_v1.dbt_run manual__2025-08-10T18:19:30.844351+00:00 [running]> on host e94eaa51f89a
[2025-08-10T18:19:33.335+0000] {taskinstance.py:2648} INFO - Exporting env vars: AIRFLOW_CTX_DAG_OWNER='***' AIRFLOW_CTX_DAG_ID='dbt_run_pipeline_v1' AIRFLOW_CTX_TASK_ID='dbt_run' AIRFLOW_CTX_EXECUTION_DATE='2025-08-10T18:19:30.844351+00:00' AIRFLOW_CTX_TRY_NUMBER='1' AIRFLOW_CTX_DAG_RUN_ID='manual__2025-08-10T18:19:30.844351+00:00'
[2025-08-10T18:19:33.341+0000] {taskinstance.py:430} INFO - ::endgroup::
[2025-08-10T18:19:33.365+0000] {subprocess.py:63} INFO - Tmp dir root location: /tmp
[2025-08-10T18:19:33.366+0000] {subprocess.py:75} INFO - Running command: ['/usr/bin/bash', '-c', 'dbt run']
[2025-08-10T18:19:33.387+0000] {subprocess.py:86} INFO - Output:
[2025-08-10T18:19:37.022+0000] {subprocess.py:93} INFO - [0m18:19:37  Running with dbt=1.10.7
[2025-08-10T18:19:41.644+0000] {subprocess.py:93} INFO - [0m18:19:41  Registered adapter: bigquery=1.10.1
[2025-08-10T18:19:43.433+0000] {subprocess.py:93} INFO - [0m18:19:43  Found 8 models, 4 sources, 496 macros
[2025-08-10T18:19:43.441+0000] {subprocess.py:93} INFO - [0m18:19:43
[2025-08-10T18:19:43.443+0000] {subprocess.py:93} INFO - [0m18:19:43  Concurrency: 1 threads (target='dev')
[2025-08-10T18:19:43.445+0000] {subprocess.py:93} INFO - [0m18:19:43
[2025-08-10T18:19:45.792+0000] {subprocess.py:93} INFO - [0m18:19:45  1 of 8 START sql view model transaction_analytics.stg_cards .................... [RUN]
[2025-08-10T18:19:48.000+0000] {subprocess.py:93} INFO - [0m18:19:48  1 of 8 OK created sql view model transaction_analytics.stg_cards ............... [[32mCREATE VIEW (0 processed)[0m in 2.19s]
[2025-08-10T18:19:48.011+0000] {subprocess.py:93} INFO - [0m18:19:48  2 of 8 START sql view model transaction_analytics.stg_mcc ...................... [RUN]
[2025-08-10T18:19:49.991+0000] {subprocess.py:93} INFO - [0m18:19:49  2 of 8 OK created sql view model transaction_analytics.stg_mcc ................. [[32mCREATE VIEW (0 processed)[0m in 1.97s]
[2025-08-10T18:19:49.996+0000] {subprocess.py:93} INFO - [0m18:19:49  3 of 8 START sql view model transaction_analytics.stg_transactions ............. [RUN]
[2025-08-10T18:19:52.316+0000] {subprocess.py:93} INFO - [0m18:19:52  3 of 8 OK created sql view model transaction_analytics.stg_transactions ........ [[32mCREATE VIEW (0 processed)[0m in 2.31s]
[2025-08-10T18:19:52.325+0000] {subprocess.py:93} INFO - [0m18:19:52  4 of 8 START sql view model transaction_analytics.stg_users .................... [RUN]
[2025-08-10T18:19:54.434+0000] {subprocess.py:93} INFO - [0m18:19:54  4 of 8 OK created sql view model transaction_analytics.stg_users ............... [[32mCREATE VIEW (0 processed)[0m in 2.10s]
[2025-08-10T18:19:54.440+0000] {subprocess.py:93} INFO - [0m18:19:54  5 of 8 START sql view model transaction_analytics.dim_cards .................... [RUN]
[2025-08-10T18:19:56.864+0000] {subprocess.py:93} INFO - [0m18:19:56  5 of 8 OK created sql view model transaction_analytics.dim_cards ............... [[32mCREATE VIEW (0 processed)[0m in 2.42s]
[2025-08-10T18:19:56.875+0000] {subprocess.py:93} INFO - [0m18:19:56  6 of 8 START sql view model transaction_analytics.dim_mcc_codes ................ [RUN]
[2025-08-10T18:19:59.693+0000] {subprocess.py:93} INFO - [0m18:19:59  6 of 8 OK created sql view model transaction_analytics.dim_mcc_codes ........... [[32mCREATE VIEW (0 processed)[0m in 2.81s]
[2025-08-10T18:19:59.698+0000] {subprocess.py:93} INFO - [0m18:19:59  7 of 8 START sql view model transaction_analytics.dim_users .................... [RUN]
[2025-08-10T18:20:02.325+0000] {subprocess.py:93} INFO - [0m18:20:02  7 of 8 OK created sql view model transaction_analytics.dim_users ............... [[32mCREATE VIEW (0 processed)[0m in 2.62s]
[2025-08-10T18:20:02.333+0000] {subprocess.py:93} INFO - [0m18:20:02  8 of 8 START sql view model transaction_analytics.fct_transactions ............. [RUN]
[2025-08-10T18:20:04.503+0000] {subprocess.py:93} INFO - [0m18:20:04  BigQuery adapter: https://console.cloud.google.com/bigquery?project=dataverse-360&j=bq:europe-west2:9c54d785-394c-45bf-b4b8-5b356b338867&page=queryresults
[2025-08-10T18:20:04.528+0000] {subprocess.py:93} INFO - [0m18:20:04  8 of 8 ERROR creating sql view model transaction_analytics.fct_transactions .... [[31mERROR[0m in 2.19s]
[2025-08-10T18:20:04.618+0000] {subprocess.py:93} INFO - [0m18:20:04
[2025-08-10T18:20:04.620+0000] {subprocess.py:93} INFO - [0m18:20:04  Finished running 8 view models in 0 hours 0 minutes and 21.17 seconds (21.17s).
[2025-08-10T18:20:04.755+0000] {subprocess.py:93} INFO - [0m18:20:04
[2025-08-10T18:20:04.758+0000] {subprocess.py:93} INFO - [0m18:20:04  [31mCompleted with 1 error, 0 partial successes, and 0 warnings:[0m
[2025-08-10T18:20:04.760+0000] {subprocess.py:93} INFO - [0m18:20:04
[2025-08-10T18:20:04.762+0000] {subprocess.py:93} INFO - [0m18:20:04  [31mFailure in model fct_transactions (models/marts/fct_transactions.sql)[0m
[2025-08-10T18:20:04.764+0000] {subprocess.py:93} INFO - [0m18:20:04    Database Error in model fct_transactions (models/marts/fct_transactions.sql)
[2025-08-10T18:20:04.765+0000] {subprocess.py:93} INFO -   Column name client_id is ambiguous at [9:1]
[2025-08-10T18:20:04.766+0000] {subprocess.py:93} INFO -   compiled code at target/run/transaction_analytics/models/marts/fct_transactions.sql
[2025-08-10T18:20:04.766+0000] {subprocess.py:93} INFO - [0m18:20:04
[2025-08-10T18:20:04.768+0000] {subprocess.py:93} INFO - [0m18:20:04    compiled code at target/compiled/transaction_analytics/models/marts/fct_transactions.sql
[2025-08-10T18:20:04.770+0000] {subprocess.py:93} INFO - [0m18:20:04
[2025-08-10T18:20:04.771+0000] {subprocess.py:93} INFO - [0m18:20:04  Done. PASS=7 WARN=0 ERROR=1 SKIP=0 NO-OP=0 TOTAL=8
[2025-08-10T18:20:07.693+0000] {subprocess.py:97} INFO - Command exited with return code 1
[2025-08-10T18:20:07.694+0000] {taskinstance.py:441} INFO - ::group::Post task execution logs
[2025-08-10T18:20:07.713+0000] {taskinstance.py:2905} ERROR - Task failed with exception
Traceback (most recent call last):
  File "/home/airflow/.local/lib/python3.12/site-packages/airflow/models/taskinstance.py", line 465, in _execute_task
    result = _execute_callable(context=context, **execute_callable_kwargs)
             ^^^^^^^^^^^^^^^^^^^^^^^^^^^^^^^^^^^^^^^^^^^^^^^^^^^^^^^^^^^^^
  File "/home/airflow/.local/lib/python3.12/site-packages/airflow/models/taskinstance.py", line 432, in _execute_callable
    return execute_callable(context=context, **execute_callable_kwargs)
           ^^^^^^^^^^^^^^^^^^^^^^^^^^^^^^^^^^^^^^^^^^^^^^^^^^^^^^^^^^^^
  File "/home/airflow/.local/lib/python3.12/site-packages/airflow/models/baseoperator.py", line 401, in wrapper
    return func(self, *args, **kwargs)
           ^^^^^^^^^^^^^^^^^^^^^^^^^^^
  File "/home/airflow/.local/lib/python3.12/site-packages/airflow/operators/bash.py", line 243, in execute
    raise AirflowException(
airflow.exceptions.AirflowException: Bash command failed. The command returned a non-zero exit code 1.
[2025-08-10T18:20:07.719+0000] {taskinstance.py:1206} INFO - Marking task as FAILED. dag_id=dbt_run_pipeline_v1, task_id=dbt_run, run_id=manual__2025-08-10T18:19:30.844351+00:00, execution_date=20250810T181930, start_date=20250810T181932, end_date=20250810T182007
[2025-08-10T18:20:07.753+0000] {standard_task_runner.py:110} ERROR - Failed to execute job 3 for task dbt_run (Bash command failed. The command returned a non-zero exit code 1.; 242)
[2025-08-10T18:20:07.790+0000] {local_task_job_runner.py:240} INFO - Task exited with return code 1
[2025-08-10T18:20:07.816+0000] {taskinstance.py:3503} INFO - 0 downstream tasks scheduled from follow-on schedule check
[2025-08-10T18:20:07.829+0000] {local_task_job_runner.py:222} INFO - ::endgroup::
