[2025-08-10T18:24:11.122+0000] {local_task_job_runner.py:120} INFO - ::group::Pre task execution logs
[2025-08-10T18:24:11.164+0000] {taskinstance.py:2076} INFO - Dependencies all met for dep_context=non-requeueable deps ti=<TaskInstance: dbt_run_pipeline_v1.dbt_run manual__2025-08-10T18:24:08.254628+00:00 [queued]>
[2025-08-10T18:24:11.178+0000] {taskinstance.py:2076} INFO - Dependencies all met for dep_context=requeueable deps ti=<TaskInstance: dbt_run_pipeline_v1.dbt_run manual__2025-08-10T18:24:08.254628+00:00 [queued]>
[2025-08-10T18:24:11.189+0000] {taskinstance.py:2306} INFO - Starting attempt 1 of 1
[2025-08-10T18:24:11.211+0000] {taskinstance.py:2330} INFO - Executing <Task(BashOperator): dbt_run> on 2025-08-10 18:24:08.254628+00:00
[2025-08-10T18:24:11.223+0000] {warnings.py:112} WARNING - /home/***/.local/lib/python3.12/site-packages/***/task/task_runner/standard_task_runner.py:61: DeprecationWarning: This process (pid=390) is multi-threaded, use of fork() may lead to deadlocks in the child.
  pid = os.fork()

[2025-08-10T18:24:11.226+0000] {standard_task_runner.py:63} INFO - Started process 391 to run task
[2025-08-10T18:24:11.225+0000] {standard_task_runner.py:90} INFO - Running: ['***', 'tasks', 'run', 'dbt_run_pipeline_v1', 'dbt_run', 'manual__2025-08-10T18:24:08.254628+00:00', '--job-id', '5', '--raw', '--subdir', 'DAGS_FOLDER/dbt_run_pipeline_v1.py', '--cfg-path', '/tmp/tmpah3nr332']
[2025-08-10T18:24:11.228+0000] {standard_task_runner.py:91} INFO - Job 5: Subtask dbt_run
[2025-08-10T18:24:11.342+0000] {task_command.py:426} INFO - Running <TaskInstance: dbt_run_pipeline_v1.dbt_run manual__2025-08-10T18:24:08.254628+00:00 [running]> on host e94eaa51f89a
[2025-08-10T18:24:11.510+0000] {taskinstance.py:2648} INFO - Exporting env vars: AIRFLOW_CTX_DAG_OWNER='***' AIRFLOW_CTX_DAG_ID='dbt_run_pipeline_v1' AIRFLOW_CTX_TASK_ID='dbt_run' AIRFLOW_CTX_EXECUTION_DATE='2025-08-10T18:24:08.254628+00:00' AIRFLOW_CTX_TRY_NUMBER='1' AIRFLOW_CTX_DAG_RUN_ID='manual__2025-08-10T18:24:08.254628+00:00'
[2025-08-10T18:24:11.511+0000] {taskinstance.py:430} INFO - ::endgroup::
[2025-08-10T18:24:11.534+0000] {subprocess.py:63} INFO - Tmp dir root location: /tmp
[2025-08-10T18:24:11.535+0000] {subprocess.py:75} INFO - Running command: ['/usr/bin/bash', '-c', 'dbt run']
[2025-08-10T18:24:11.554+0000] {subprocess.py:86} INFO - Output:
[2025-08-10T18:24:14.978+0000] {subprocess.py:93} INFO - [0m18:24:14  Running with dbt=1.10.7
[2025-08-10T18:24:19.250+0000] {subprocess.py:93} INFO - [0m18:24:19  Registered adapter: bigquery=1.10.1
[2025-08-10T18:24:20.287+0000] {subprocess.py:93} INFO - [0m18:24:20  Found 8 models, 4 sources, 496 macros
[2025-08-10T18:24:20.293+0000] {subprocess.py:93} INFO - [0m18:24:20
[2025-08-10T18:24:20.295+0000] {subprocess.py:93} INFO - [0m18:24:20  Concurrency: 1 threads (target='dev')
[2025-08-10T18:24:20.297+0000] {subprocess.py:93} INFO - [0m18:24:20
[2025-08-10T18:24:22.396+0000] {subprocess.py:93} INFO - [0m18:24:22  1 of 8 START sql view model transaction_analytics.stg_cards .................... [RUN]
[2025-08-10T18:24:24.473+0000] {subprocess.py:93} INFO - [0m18:24:24  1 of 8 OK created sql view model transaction_analytics.stg_cards ............... [[32mCREATE VIEW (0 processed)[0m in 2.07s]
[2025-08-10T18:24:24.481+0000] {subprocess.py:93} INFO - [0m18:24:24  2 of 8 START sql view model transaction_analytics.stg_mcc ...................... [RUN]
[2025-08-10T18:24:26.431+0000] {subprocess.py:93} INFO - [0m18:24:26  2 of 8 OK created sql view model transaction_analytics.stg_mcc ................. [[32mCREATE VIEW (0 processed)[0m in 1.94s]
[2025-08-10T18:24:26.437+0000] {subprocess.py:93} INFO - [0m18:24:26  3 of 8 START sql view model transaction_analytics.stg_transactions ............. [RUN]
[2025-08-10T18:24:28.215+0000] {subprocess.py:93} INFO - [0m18:24:28  3 of 8 OK created sql view model transaction_analytics.stg_transactions ........ [[32mCREATE VIEW (0 processed)[0m in 1.77s]
[2025-08-10T18:24:28.221+0000] {subprocess.py:93} INFO - [0m18:24:28  4 of 8 START sql view model transaction_analytics.stg_users .................... [RUN]
[2025-08-10T18:24:30.344+0000] {subprocess.py:93} INFO - [0m18:24:30  4 of 8 OK created sql view model transaction_analytics.stg_users ............... [[32mCREATE VIEW (0 processed)[0m in 2.12s]
[2025-08-10T18:24:30.350+0000] {subprocess.py:93} INFO - [0m18:24:30  5 of 8 START sql view model transaction_analytics.dim_cards .................... [RUN]
[2025-08-10T18:24:32.254+0000] {subprocess.py:93} INFO - [0m18:24:32  5 of 8 OK created sql view model transaction_analytics.dim_cards ............... [[32mCREATE VIEW (0 processed)[0m in 1.90s]
[2025-08-10T18:24:32.262+0000] {subprocess.py:93} INFO - [0m18:24:32  6 of 8 START sql view model transaction_analytics.dim_mcc_codes ................ [RUN]
[2025-08-10T18:24:34.458+0000] {subprocess.py:93} INFO - [0m18:24:34  6 of 8 OK created sql view model transaction_analytics.dim_mcc_codes ........... [[32mCREATE VIEW (0 processed)[0m in 2.19s]
[2025-08-10T18:24:34.463+0000] {subprocess.py:93} INFO - [0m18:24:34  7 of 8 START sql view model transaction_analytics.dim_users .................... [RUN]
[2025-08-10T18:24:36.335+0000] {subprocess.py:93} INFO - [0m18:24:36  7 of 8 OK created sql view model transaction_analytics.dim_users ............... [[32mCREATE VIEW (0 processed)[0m in 1.86s]
[2025-08-10T18:24:36.347+0000] {subprocess.py:93} INFO - [0m18:24:36  8 of 8 START sql view model transaction_analytics.fct_transactions ............. [RUN]
[2025-08-10T18:24:38.769+0000] {subprocess.py:93} INFO - [0m18:24:38  BigQuery adapter: https://console.cloud.google.com/bigquery?project=dataverse-360&j=bq:europe-west2:c43f9539-b253-479a-9ee9-40a47dc0f8cb&page=queryresults
[2025-08-10T18:24:38.791+0000] {subprocess.py:93} INFO - [0m18:24:38  8 of 8 ERROR creating sql view model transaction_analytics.fct_transactions .... [[31mERROR[0m in 2.44s]
[2025-08-10T18:24:38.871+0000] {subprocess.py:93} INFO - [0m18:24:38
[2025-08-10T18:24:38.873+0000] {subprocess.py:93} INFO - [0m18:24:38  Finished running 8 view models in 0 hours 0 minutes and 18.57 seconds (18.57s).
[2025-08-10T18:24:38.983+0000] {subprocess.py:93} INFO - [0m18:24:38
[2025-08-10T18:24:38.984+0000] {subprocess.py:93} INFO - [0m18:24:38  [31mCompleted with 1 error, 0 partial successes, and 0 warnings:[0m
[2025-08-10T18:24:38.986+0000] {subprocess.py:93} INFO - [0m18:24:38
[2025-08-10T18:24:38.988+0000] {subprocess.py:93} INFO - [0m18:24:38  [31mFailure in model fct_transactions (models/marts/fct_transactions.sql)[0m
[2025-08-10T18:24:38.990+0000] {subprocess.py:93} INFO - [0m18:24:38    Database Error in model fct_transactions (models/marts/fct_transactions.sql)
[2025-08-10T18:24:38.991+0000] {subprocess.py:93} INFO -   Column name card_id is ambiguous at [10:1]
[2025-08-10T18:24:38.991+0000] {subprocess.py:93} INFO -   compiled code at target/run/transaction_analytics/models/marts/fct_transactions.sql
[2025-08-10T18:24:38.992+0000] {subprocess.py:93} INFO - [0m18:24:38
[2025-08-10T18:24:38.994+0000] {subprocess.py:93} INFO - [0m18:24:38    compiled code at target/compiled/transaction_analytics/models/marts/fct_transactions.sql
[2025-08-10T18:24:38.995+0000] {subprocess.py:93} INFO - [0m18:24:38
[2025-08-10T18:24:38.997+0000] {subprocess.py:93} INFO - [0m18:24:38  Done. PASS=7 WARN=0 ERROR=1 SKIP=0 NO-OP=0 TOTAL=8
[2025-08-10T18:24:42.277+0000] {subprocess.py:97} INFO - Command exited with return code 1
[2025-08-10T18:24:42.278+0000] {taskinstance.py:441} INFO - ::group::Post task execution logs
[2025-08-10T18:24:42.296+0000] {taskinstance.py:2905} ERROR - Task failed with exception
Traceback (most recent call last):
  File "/home/airflow/.local/lib/python3.12/site-packages/airflow/models/taskinstance.py", line 465, in _execute_task
    result = _execute_callable(context=context, **execute_callable_kwargs)
             ^^^^^^^^^^^^^^^^^^^^^^^^^^^^^^^^^^^^^^^^^^^^^^^^^^^^^^^^^^^^^
  File "/home/airflow/.local/lib/python3.12/site-packages/airflow/models/taskinstance.py", line 432, in _execute_callable
    return execute_callable(context=context, **execute_callable_kwargs)
           ^^^^^^^^^^^^^^^^^^^^^^^^^^^^^^^^^^^^^^^^^^^^^^^^^^^^^^^^^^^^
  File "/home/airflow/.local/lib/python3.12/site-packages/airflow/models/baseoperator.py", line 401, in wrapper
    return func(self, *args, **kwargs)
           ^^^^^^^^^^^^^^^^^^^^^^^^^^^
  File "/home/airflow/.local/lib/python3.12/site-packages/airflow/operators/bash.py", line 243, in execute
    raise AirflowException(
airflow.exceptions.AirflowException: Bash command failed. The command returned a non-zero exit code 1.
[2025-08-10T18:24:42.302+0000] {taskinstance.py:1206} INFO - Marking task as FAILED. dag_id=dbt_run_pipeline_v1, task_id=dbt_run, run_id=manual__2025-08-10T18:24:08.254628+00:00, execution_date=20250810T182408, start_date=20250810T182411, end_date=20250810T182442
[2025-08-10T18:24:42.333+0000] {standard_task_runner.py:110} ERROR - Failed to execute job 5 for task dbt_run (Bash command failed. The command returned a non-zero exit code 1.; 391)
[2025-08-10T18:24:42.374+0000] {local_task_job_runner.py:240} INFO - Task exited with return code 1
[2025-08-10T18:24:42.399+0000] {taskinstance.py:3503} INFO - 0 downstream tasks scheduled from follow-on schedule check
[2025-08-10T18:24:42.403+0000] {local_task_job_runner.py:222} INFO - ::endgroup::
