[2025-08-02T16:55:24.454+0000] {local_task_job_runner.py:120} INFO - ::group::Pre task execution logs
[2025-08-02T16:55:24.486+0000] {taskinstance.py:2076} INFO - Dependencies all met for dep_context=non-requeueable deps ti=<TaskInstance: gcs_extract_and_load_v1.process_and_load_json_to_gcs manual__2025-08-02T16:55:13.577782+00:00 [queued]>
[2025-08-02T16:55:24.498+0000] {taskinstance.py:2076} INFO - Dependencies all met for dep_context=requeueable deps ti=<TaskInstance: gcs_extract_and_load_v1.process_and_load_json_to_gcs manual__2025-08-02T16:55:13.577782+00:00 [queued]>
[2025-08-02T16:55:24.501+0000] {taskinstance.py:2306} INFO - Starting attempt 1 of 1
[2025-08-02T16:55:24.526+0000] {taskinstance.py:2330} INFO - Executing <Task(PythonOperator): process_and_load_json_to_gcs> on 2025-08-02 16:55:13.577782+00:00
[2025-08-02T16:55:24.543+0000] {warnings.py:112} WARNING - /home/***/.local/lib/python3.12/site-packages/***/task/task_runner/standard_task_runner.py:61: DeprecationWarning: This process (pid=702) is multi-threaded, use of fork() may lead to deadlocks in the child.
  pid = os.fork()

[2025-08-02T16:55:24.546+0000] {standard_task_runner.py:63} INFO - Started process 717 to run task
[2025-08-02T16:55:24.547+0000] {standard_task_runner.py:90} INFO - Running: ['***', 'tasks', 'run', 'gcs_extract_and_load_v1', 'process_and_load_json_to_gcs', 'manual__2025-08-02T16:55:13.577782+00:00', '--job-id', '8', '--raw', '--subdir', 'DAGS_FOLDER/gcs_load_dag.py', '--cfg-path', '/tmp/tmp8etpg0qy']
[2025-08-02T16:55:24.549+0000] {standard_task_runner.py:91} INFO - Job 8: Subtask process_and_load_json_to_gcs
[2025-08-02T16:55:24.659+0000] {task_command.py:426} INFO - Running <TaskInstance: gcs_extract_and_load_v1.process_and_load_json_to_gcs manual__2025-08-02T16:55:13.577782+00:00 [running]> on host 98321bfe6108
[2025-08-02T16:55:24.837+0000] {taskinstance.py:2648} INFO - Exporting env vars: AIRFLOW_CTX_DAG_OWNER='***' AIRFLOW_CTX_DAG_ID='gcs_extract_and_load_v1' AIRFLOW_CTX_TASK_ID='process_and_load_json_to_gcs' AIRFLOW_CTX_EXECUTION_DATE='2025-08-02T16:55:13.577782+00:00' AIRFLOW_CTX_TRY_NUMBER='1' AIRFLOW_CTX_DAG_RUN_ID='manual__2025-08-02T16:55:13.577782+00:00'
[2025-08-02T16:55:24.845+0000] {taskinstance.py:430} INFO - ::endgroup::
[2025-08-02T16:55:25.390+0000] {connection.py:274} WARNING - Connection schemes (type: google_cloud_platform) shall not contain '_' according to RFC3986.
[2025-08-02T16:55:25.394+0000] {base.py:84} INFO - Using connection ID 'google_cloud_default' for task execution.
[2025-08-02T16:55:25.413+0000] {taskinstance.py:441} INFO - ::group::Post task execution logs
[2025-08-02T16:55:25.414+0000] {taskinstance.py:2905} ERROR - Task failed with exception
Traceback (most recent call last):
  File "/home/airflow/.local/lib/python3.12/site-packages/airflow/models/taskinstance.py", line 465, in _execute_task
    result = _execute_callable(context=context, **execute_callable_kwargs)
             ^^^^^^^^^^^^^^^^^^^^^^^^^^^^^^^^^^^^^^^^^^^^^^^^^^^^^^^^^^^^^
  File "/home/airflow/.local/lib/python3.12/site-packages/airflow/models/taskinstance.py", line 432, in _execute_callable
    return execute_callable(context=context, **execute_callable_kwargs)
           ^^^^^^^^^^^^^^^^^^^^^^^^^^^^^^^^^^^^^^^^^^^^^^^^^^^^^^^^^^^^
  File "/home/airflow/.local/lib/python3.12/site-packages/airflow/models/baseoperator.py", line 401, in wrapper
    return func(self, *args, **kwargs)
           ^^^^^^^^^^^^^^^^^^^^^^^^^^^
  File "/home/airflow/.local/lib/python3.12/site-packages/airflow/operators/python.py", line 235, in execute
    return_value = self.execute_callable()
                   ^^^^^^^^^^^^^^^^^^^^^^^
  File "/home/airflow/.local/lib/python3.12/site-packages/airflow/operators/python.py", line 252, in execute_callable
    return self.python_callable(*self.op_args, **self.op_kwargs)
           ^^^^^^^^^^^^^^^^^^^^^^^^^^^^^^^^^^^^^^^^^^^^^^^^^^^^^
  File "/opt/airflow/dags/gcs_load_dag.py", line 42, in process_and_upload_json
    with open(local_json_path, 'r') as f:
         ^^^^^^^^^^^^^^^^^^^^^^^^^^
FileNotFoundError: [Errno 2] No such file or directory: '/opt/airflow/dags/data/customer_data.json'
[2025-08-02T16:55:25.441+0000] {taskinstance.py:1206} INFO - Marking task as FAILED. dag_id=gcs_extract_and_load_v1, task_id=process_and_load_json_to_gcs, run_id=manual__2025-08-02T16:55:13.577782+00:00, execution_date=20250802T165513, start_date=20250802T165524, end_date=20250802T165525
[2025-08-02T16:55:25.461+0000] {standard_task_runner.py:110} ERROR - Failed to execute job 8 for task process_and_load_json_to_gcs ([Errno 2] No such file or directory: '/opt/airflow/dags/data/customer_data.json'; 717)
[2025-08-02T16:55:25.569+0000] {local_task_job_runner.py:240} INFO - Task exited with return code 1
[2025-08-02T16:55:25.589+0000] {local_task_job_runner.py:222} INFO - ::endgroup::
