[2025-08-02T21:33:31.672+0000] {local_task_job_runner.py:120} INFO - ::group::Pre task execution logs
[2025-08-02T21:33:31.695+0000] {taskinstance.py:2076} INFO - Dependencies all met for dep_context=non-requeueable deps ti=<TaskInstance: gcs_move_landing_to_raw_v1.move_transactions_file manual__2025-08-02T21:33:27.665686+00:00 [queued]>
[2025-08-02T21:33:31.706+0000] {taskinstance.py:2076} INFO - Dependencies all met for dep_context=requeueable deps ti=<TaskInstance: gcs_move_landing_to_raw_v1.move_transactions_file manual__2025-08-02T21:33:27.665686+00:00 [queued]>
[2025-08-02T21:33:31.708+0000] {taskinstance.py:2306} INFO - Starting attempt 1 of 1
[2025-08-02T21:33:31.725+0000] {taskinstance.py:2330} INFO - Executing <Task(GCSToGCSOperator): move_transactions_file> on 2025-08-02 21:33:27.665686+00:00
[2025-08-02T21:33:31.741+0000] {warnings.py:112} WARNING - /home/***/.local/lib/python3.12/site-packages/***/task/task_runner/standard_task_runner.py:61: DeprecationWarning: This process (pid=731) is multi-threaded, use of fork() may lead to deadlocks in the child.
  pid = os.fork()

[2025-08-02T21:33:31.745+0000] {standard_task_runner.py:63} INFO - Started process 738 to run task
[2025-08-02T21:33:31.745+0000] {standard_task_runner.py:90} INFO - Running: ['***', 'tasks', 'run', 'gcs_move_landing_to_raw_v1', 'move_transactions_file', 'manual__2025-08-02T21:33:27.665686+00:00', '--job-id', '38', '--raw', '--subdir', 'DAGS_FOLDER/gcs_load_dag.py', '--cfg-path', '/tmp/tmpnpot5qkt']
[2025-08-02T21:33:31.750+0000] {standard_task_runner.py:91} INFO - Job 38: Subtask move_transactions_file
[2025-08-02T21:33:31.848+0000] {task_command.py:426} INFO - Running <TaskInstance: gcs_move_landing_to_raw_v1.move_transactions_file manual__2025-08-02T21:33:27.665686+00:00 [running]> on host 06d424bf0ee1
[2025-08-02T21:33:32.003+0000] {taskinstance.py:2648} INFO - Exporting env vars: AIRFLOW_CTX_DAG_OWNER='***' AIRFLOW_CTX_DAG_ID='gcs_move_landing_to_raw_v1' AIRFLOW_CTX_TASK_ID='move_transactions_file' AIRFLOW_CTX_EXECUTION_DATE='2025-08-02T21:33:27.665686+00:00' AIRFLOW_CTX_TRY_NUMBER='1' AIRFLOW_CTX_DAG_RUN_ID='manual__2025-08-02T21:33:27.665686+00:00'
[2025-08-02T21:33:32.007+0000] {taskinstance.py:430} INFO - ::endgroup::
[2025-08-02T21:33:32.021+0000] {connection.py:274} WARNING - Connection schemes (type: google_cloud_platform) shall not contain '_' according to RFC3986.
[2025-08-02T21:33:32.025+0000] {base.py:84} INFO - Using connection ID 'google_cloud_default' for task execution.
[2025-08-02T21:33:32.026+0000] {taskinstance.py:441} INFO - ::group::Post task execution logs
[2025-08-02T21:33:32.027+0000] {taskinstance.py:2905} ERROR - Task failed with exception
Traceback (most recent call last):
  File "/home/airflow/.local/lib/python3.12/site-packages/airflow/models/taskinstance.py", line 465, in _execute_task
    result = _execute_callable(context=context, **execute_callable_kwargs)
             ^^^^^^^^^^^^^^^^^^^^^^^^^^^^^^^^^^^^^^^^^^^^^^^^^^^^^^^^^^^^^
  File "/home/airflow/.local/lib/python3.12/site-packages/airflow/models/taskinstance.py", line 432, in _execute_callable
    return execute_callable(context=context, **execute_callable_kwargs)
           ^^^^^^^^^^^^^^^^^^^^^^^^^^^^^^^^^^^^^^^^^^^^^^^^^^^^^^^^^^^^
  File "/home/airflow/.local/lib/python3.12/site-packages/airflow/models/baseoperator.py", line 401, in wrapper
    return func(self, *args, **kwargs)
           ^^^^^^^^^^^^^^^^^^^^^^^^^^^
  File "/home/airflow/.local/lib/python3.12/site-packages/airflow/providers/google/cloud/transfers/gcs_to_gcs.py", line 281, in execute
    self._copy_source_without_wildcard(hook=hook, prefix=prefix)
  File "/home/airflow/.local/lib/python3.12/site-packages/airflow/providers/google/cloud/transfers/gcs_to_gcs.py", line 388, in _copy_source_without_wildcard
    objects = hook.list(
              ^^^^^^^^^^
  File "/home/airflow/.local/lib/python3.12/site-packages/airflow/providers/google/cloud/hooks/gcs.py", line 768, in list
    self._list(
  File "/home/airflow/.local/lib/python3.12/site-packages/airflow/providers/google/cloud/hooks/gcs.py", line 804, in _list
    client = self.get_conn()
             ^^^^^^^^^^^^^^^
  File "/home/airflow/.local/lib/python3.12/site-packages/airflow/providers/google/cloud/hooks/gcs.py", line 173, in get_conn
    credentials=self.get_credentials(), client_info=CLIENT_INFO, project=self.project_id
                ^^^^^^^^^^^^^^^^^^^^^^
  File "/home/airflow/.local/lib/python3.12/site-packages/airflow/providers/google/common/hooks/base_google.py", line 332, in get_credentials
    credentials, _ = self.get_credentials_and_project_id()
                     ^^^^^^^^^^^^^^^^^^^^^^^^^^^^^^^^^^^^^
  File "/home/airflow/.local/lib/python3.12/site-packages/airflow/providers/google/common/hooks/base_google.py", line 308, in get_credentials_and_project_id
    credentials, project_id = get_credentials_and_project_id(
                              ^^^^^^^^^^^^^^^^^^^^^^^^^^^^^^^
  File "/home/airflow/.local/lib/python3.12/site-packages/airflow/providers/google/cloud/utils/credentials_provider.py", line 371, in get_credentials_and_project_id
    return _CredentialProvider(*args, **kwargs).get_credentials_and_project()
           ^^^^^^^^^^^^^^^^^^^^^^^^^^^^^^^^^^^^^^^^^^^^^^^^^^^^^^^^^^^^^^^^^^
  File "/home/airflow/.local/lib/python3.12/site-packages/airflow/providers/google/cloud/utils/credentials_provider.py", line 245, in get_credentials_and_project
    credentials, project_id = self._get_credentials_using_key_path()
                              ^^^^^^^^^^^^^^^^^^^^^^^^^^^^^^^^^^^^^^
  File "/home/airflow/.local/lib/python3.12/site-packages/airflow/providers/google/cloud/utils/credentials_provider.py", line 295, in _get_credentials_using_key_path
    credentials = google.oauth2.service_account.Credentials.from_service_account_file(
                  ^^^^^^^^^^^^^^^^^^^^^^^^^^^^^^^^^^^^^^^^^^^^^^^^^^^^^^^^^^^^^^^^^^^^
  File "/home/airflow/.local/lib/python3.12/site-packages/google/oauth2/service_account.py", line 258, in from_service_account_file
    info, signer = _service_account_info.from_filename(
                   ^^^^^^^^^^^^^^^^^^^^^^^^^^^^^^^^^^^^
  File "/home/airflow/.local/lib/python3.12/site-packages/google/auth/_service_account_info.py", line 78, in from_filename
    with io.open(filename, "r", encoding="utf-8") as json_file:
         ^^^^^^^^^^^^^^^^^^^^^^^^^^^^^^^^^^^^^^^^
FileNotFoundError: [Errno 2] No such file or directory: 'C:/Users/RSK_T14s/Documents/Full Stack Data Project/Dataverse-360/airflow/gcp/dataverse-360-4ac58a9dbd94.json'
[2025-08-02T21:33:32.046+0000] {taskinstance.py:1206} INFO - Marking task as FAILED. dag_id=gcs_move_landing_to_raw_v1, task_id=move_transactions_file, run_id=manual__2025-08-02T21:33:27.665686+00:00, execution_date=20250802T213327, start_date=20250802T213331, end_date=20250802T213332
[2025-08-02T21:33:32.073+0000] {standard_task_runner.py:110} ERROR - Failed to execute job 38 for task move_transactions_file ([Errno 2] No such file or directory: 'C:/Users/RSK_T14s/Documents/Full Stack Data Project/Dataverse-360/airflow/gcp/dataverse-360-4ac58a9dbd94.json'; 738)
[2025-08-02T21:33:32.121+0000] {local_task_job_runner.py:240} INFO - Task exited with return code 1
[2025-08-02T21:33:32.135+0000] {local_task_job_runner.py:222} INFO - ::endgroup::
