[2025-08-09T18:53:40.253+0000] {local_task_job_runner.py:120} INFO - ::group::Pre task execution logs
[2025-08-09T18:53:40.283+0000] {taskinstance.py:2076} INFO - Dependencies all met for dep_context=non-requeueable deps ti=<TaskInstance: dbt_run_pipeline_v1.dbt_run manual__2025-08-09T18:53:36.103343+00:00 [queued]>
[2025-08-09T18:53:40.290+0000] {taskinstance.py:2076} INFO - Dependencies all met for dep_context=requeueable deps ti=<TaskInstance: dbt_run_pipeline_v1.dbt_run manual__2025-08-09T18:53:36.103343+00:00 [queued]>
[2025-08-09T18:53:40.292+0000] {taskinstance.py:2306} INFO - Starting attempt 1 of 1
[2025-08-09T18:53:40.306+0000] {taskinstance.py:2330} INFO - Executing <Task(BashOperator): dbt_run> on 2025-08-09 18:53:36.103343+00:00
[2025-08-09T18:53:40.315+0000] {warnings.py:112} WARNING - /home/***/.local/lib/python3.12/site-packages/***/task/task_runner/standard_task_runner.py:61: DeprecationWarning: This process (pid=114) is multi-threaded, use of fork() may lead to deadlocks in the child.
  pid = os.fork()

[2025-08-09T18:53:40.317+0000] {standard_task_runner.py:63} INFO - Started process 116 to run task
[2025-08-09T18:53:40.318+0000] {standard_task_runner.py:90} INFO - Running: ['***', 'tasks', 'run', 'dbt_run_pipeline_v1', 'dbt_run', 'manual__2025-08-09T18:53:36.103343+00:00', '--job-id', '100', '--raw', '--subdir', 'DAGS_FOLDER/dbt_run_pipeline_v1.py', '--cfg-path', '/tmp/tmpow2e_cii']
[2025-08-09T18:53:40.321+0000] {standard_task_runner.py:91} INFO - Job 100: Subtask dbt_run
[2025-08-09T18:53:40.397+0000] {task_command.py:426} INFO - Running <TaskInstance: dbt_run_pipeline_v1.dbt_run manual__2025-08-09T18:53:36.103343+00:00 [running]> on host 45901499a02b
[2025-08-09T18:53:40.494+0000] {taskinstance.py:2648} INFO - Exporting env vars: AIRFLOW_CTX_DAG_OWNER='***' AIRFLOW_CTX_DAG_ID='dbt_run_pipeline_v1' AIRFLOW_CTX_TASK_ID='dbt_run' AIRFLOW_CTX_EXECUTION_DATE='2025-08-09T18:53:36.103343+00:00' AIRFLOW_CTX_TRY_NUMBER='1' AIRFLOW_CTX_DAG_RUN_ID='manual__2025-08-09T18:53:36.103343+00:00'
[2025-08-09T18:53:40.499+0000] {taskinstance.py:430} INFO - ::endgroup::
[2025-08-09T18:53:40.500+0000] {taskinstance.py:441} INFO - ::group::Post task execution logs
[2025-08-09T18:53:40.510+0000] {taskinstance.py:2905} ERROR - Task failed with exception
Traceback (most recent call last):
  File "/home/airflow/.local/lib/python3.12/site-packages/airflow/models/taskinstance.py", line 465, in _execute_task
    result = _execute_callable(context=context, **execute_callable_kwargs)
             ^^^^^^^^^^^^^^^^^^^^^^^^^^^^^^^^^^^^^^^^^^^^^^^^^^^^^^^^^^^^^
  File "/home/airflow/.local/lib/python3.12/site-packages/airflow/models/taskinstance.py", line 432, in _execute_callable
    return execute_callable(context=context, **execute_callable_kwargs)
           ^^^^^^^^^^^^^^^^^^^^^^^^^^^^^^^^^^^^^^^^^^^^^^^^^^^^^^^^^^^^
  File "/home/airflow/.local/lib/python3.12/site-packages/airflow/models/baseoperator.py", line 401, in wrapper
    return func(self, *args, **kwargs)
           ^^^^^^^^^^^^^^^^^^^^^^^^^^^
  File "/home/airflow/.local/lib/python3.12/site-packages/airflow/operators/bash.py", line 220, in execute
    raise AirflowException(f"Can not find the cwd: {self.cwd}")
airflow.exceptions.AirflowException: Can not find the cwd: /opt/***/dbt
[2025-08-09T18:53:40.515+0000] {taskinstance.py:1206} INFO - Marking task as FAILED. dag_id=dbt_run_pipeline_v1, task_id=dbt_run, run_id=manual__2025-08-09T18:53:36.103343+00:00, execution_date=20250809T185336, start_date=20250809T185340, end_date=20250809T185340
[2025-08-09T18:53:40.529+0000] {standard_task_runner.py:110} ERROR - Failed to execute job 100 for task dbt_run (Can not find the cwd: /opt/***/dbt; 116)
[2025-08-09T18:53:40.573+0000] {local_task_job_runner.py:240} INFO - Task exited with return code 1
[2025-08-09T18:53:40.596+0000] {taskinstance.py:3503} INFO - 0 downstream tasks scheduled from follow-on schedule check
[2025-08-09T18:53:40.599+0000] {local_task_job_runner.py:222} INFO - ::endgroup::
