[2025-08-12T02:55:29.075+0000] {local_task_job_runner.py:120} INFO - ::group::Pre task execution logs
[2025-08-12T02:55:29.113+0000] {taskinstance.py:2076} INFO - Dependencies all met for dep_context=non-requeueable deps ti=<TaskInstance: dbt_run_pipeline_v1.dbt_run manual__2025-08-12T02:55:26.877659+00:00 [queued]>
[2025-08-12T02:55:29.126+0000] {taskinstance.py:2076} INFO - Dependencies all met for dep_context=requeueable deps ti=<TaskInstance: dbt_run_pipeline_v1.dbt_run manual__2025-08-12T02:55:26.877659+00:00 [queued]>
[2025-08-12T02:55:29.128+0000] {taskinstance.py:2306} INFO - Starting attempt 1 of 1
[2025-08-12T02:55:29.152+0000] {taskinstance.py:2330} INFO - Executing <Task(BashOperator): dbt_run> on 2025-08-12 02:55:26.877659+00:00
[2025-08-12T02:55:29.165+0000] {warnings.py:112} WARNING - /home/***/.local/lib/python3.12/site-packages/***/task/task_runner/standard_task_runner.py:61: DeprecationWarning: This process (pid=1792) is multi-threaded, use of fork() may lead to deadlocks in the child.
  pid = os.fork()

[2025-08-12T02:55:29.167+0000] {standard_task_runner.py:90} INFO - Running: ['***', 'tasks', 'run', 'dbt_run_pipeline_v1', 'dbt_run', 'manual__2025-08-12T02:55:26.877659+00:00', '--job-id', '14', '--raw', '--subdir', 'DAGS_FOLDER/dbt_run_pipeline_v1.py', '--cfg-path', '/tmp/tmp5h1knl6s']
[2025-08-12T02:55:29.168+0000] {standard_task_runner.py:63} INFO - Started process 1793 to run task
[2025-08-12T02:55:29.169+0000] {standard_task_runner.py:91} INFO - Job 14: Subtask dbt_run
[2025-08-12T02:55:29.265+0000] {task_command.py:426} INFO - Running <TaskInstance: dbt_run_pipeline_v1.dbt_run manual__2025-08-12T02:55:26.877659+00:00 [running]> on host ef2de7cf7633
[2025-08-12T02:55:29.440+0000] {taskinstance.py:2648} INFO - Exporting env vars: AIRFLOW_CTX_DAG_OWNER='***' AIRFLOW_CTX_DAG_ID='dbt_run_pipeline_v1' AIRFLOW_CTX_TASK_ID='dbt_run' AIRFLOW_CTX_EXECUTION_DATE='2025-08-12T02:55:26.877659+00:00' AIRFLOW_CTX_TRY_NUMBER='1' AIRFLOW_CTX_DAG_RUN_ID='manual__2025-08-12T02:55:26.877659+00:00'
[2025-08-12T02:55:29.442+0000] {taskinstance.py:430} INFO - ::endgroup::
[2025-08-12T02:55:29.466+0000] {subprocess.py:63} INFO - Tmp dir root location: /tmp
[2025-08-12T02:55:29.467+0000] {subprocess.py:75} INFO - Running command: ['/usr/bin/bash', '-c', 'dbt run']
[2025-08-12T02:55:29.487+0000] {subprocess.py:86} INFO - Output:
[2025-08-12T02:55:33.304+0000] {subprocess.py:93} INFO - [0m02:55:33  Running with dbt=1.10.7
[2025-08-12T02:55:38.210+0000] {subprocess.py:93} INFO - [0m02:55:38  Registered adapter: bigquery=1.10.1
[2025-08-12T02:55:38.816+0000] {subprocess.py:93} INFO - [0m02:55:38  Unable to do partial parsing because of a version mismatch
[2025-08-12T02:55:41.576+0000] {subprocess.py:93} INFO - [0m02:55:41  Found 8 models, 4 sources, 496 macros
[2025-08-12T02:55:41.581+0000] {subprocess.py:93} INFO - [0m02:55:41
[2025-08-12T02:55:41.583+0000] {subprocess.py:93} INFO - [0m02:55:41  Concurrency: 1 threads (target='dev')
[2025-08-12T02:55:41.585+0000] {subprocess.py:93} INFO - [0m02:55:41
[2025-08-12T02:55:43.977+0000] {subprocess.py:93} INFO - [0m02:55:43  1 of 8 START sql view model transaction_analytics.stg_cards .................... [RUN]
[2025-08-12T02:55:46.014+0000] {subprocess.py:93} INFO - [0m02:55:46  1 of 8 OK created sql view model transaction_analytics.stg_cards ............... [[32mCREATE VIEW (0 processed)[0m in 2.03s]
[2025-08-12T02:55:46.019+0000] {subprocess.py:93} INFO - [0m02:55:46  2 of 8 START sql view model transaction_analytics.stg_mcc ...................... [RUN]
[2025-08-12T02:55:47.809+0000] {subprocess.py:93} INFO - [0m02:55:47  2 of 8 OK created sql view model transaction_analytics.stg_mcc ................. [[32mCREATE VIEW (0 processed)[0m in 1.78s]
[2025-08-12T02:55:47.815+0000] {subprocess.py:93} INFO - [0m02:55:47  3 of 8 START sql view model transaction_analytics.stg_transactions ............. [RUN]
[2025-08-12T02:55:49.856+0000] {subprocess.py:93} INFO - [0m02:55:49  3 of 8 OK created sql view model transaction_analytics.stg_transactions ........ [[32mCREATE VIEW (0 processed)[0m in 2.03s]
[2025-08-12T02:55:49.862+0000] {subprocess.py:93} INFO - [0m02:55:49  4 of 8 START sql view model transaction_analytics.stg_users .................... [RUN]
[2025-08-12T02:55:51.686+0000] {subprocess.py:93} INFO - [0m02:55:51  4 of 8 OK created sql view model transaction_analytics.stg_users ............... [[32mCREATE VIEW (0 processed)[0m in 1.82s]
[2025-08-12T02:55:51.693+0000] {subprocess.py:93} INFO - [0m02:55:51  5 of 8 START sql view model transaction_analytics.dim_cards .................... [RUN]
[2025-08-12T02:55:54.136+0000] {subprocess.py:93} INFO - [0m02:55:54  BigQuery adapter: https://console.cloud.google.com/bigquery?project=dataverse-360&j=bq:europe-west2:f1abba5f-650a-40c6-845c-46ec3d3dd82b&page=queryresults
[2025-08-12T02:55:54.161+0000] {subprocess.py:93} INFO - [0m02:55:54  5 of 8 ERROR creating sql view model transaction_analytics.dim_cards ........... [[31mERROR[0m in 2.46s]
[2025-08-12T02:55:54.169+0000] {subprocess.py:93} INFO - [0m02:55:54  6 of 8 START sql view model transaction_analytics.dim_mcc_codes ................ [RUN]
[2025-08-12T02:55:56.313+0000] {subprocess.py:93} INFO - [0m02:55:56  6 of 8 OK created sql view model transaction_analytics.dim_mcc_codes ........... [[32mCREATE VIEW (0 processed)[0m in 2.14s]
[2025-08-12T02:55:56.320+0000] {subprocess.py:93} INFO - [0m02:55:56  7 of 8 START sql view model transaction_analytics.dim_users .................... [RUN]
[2025-08-12T02:55:58.684+0000] {subprocess.py:93} INFO - [0m02:55:58  7 of 8 OK created sql view model transaction_analytics.dim_users ............... [[32mCREATE VIEW (0 processed)[0m in 2.36s]
[2025-08-12T02:55:58.691+0000] {subprocess.py:93} INFO - [0m02:55:58  8 of 8 SKIP relation transaction_analytics.fct_transactions .................... [[33mSKIP[0m]
[2025-08-12T02:55:58.768+0000] {subprocess.py:93} INFO - [0m02:55:58
[2025-08-12T02:55:58.769+0000] {subprocess.py:93} INFO - [0m02:55:58  Finished running 8 view models in 0 hours 0 minutes and 17.18 seconds (17.18s).
[2025-08-12T02:55:58.957+0000] {subprocess.py:93} INFO - [0m02:55:58
[2025-08-12T02:55:58.959+0000] {subprocess.py:93} INFO - [0m02:55:58  [31mCompleted with 1 error, 0 partial successes, and 0 warnings:[0m
[2025-08-12T02:55:58.961+0000] {subprocess.py:93} INFO - [0m02:55:58
[2025-08-12T02:55:58.962+0000] {subprocess.py:93} INFO - [0m02:55:58  [31mFailure in model dim_cards (models/marts/dim_cards.sql)[0m
[2025-08-12T02:55:58.964+0000] {subprocess.py:93} INFO - [0m02:55:58    Database Error in model dim_cards (models/marts/dim_cards.sql)
[2025-08-12T02:55:58.964+0000] {subprocess.py:93} INFO -   Unrecognized name: card_expiry_date at [13:1]
[2025-08-12T02:55:58.965+0000] {subprocess.py:93} INFO -   compiled code at target/run/transaction_analytics/models/marts/dim_cards.sql
[2025-08-12T02:55:58.966+0000] {subprocess.py:93} INFO - [0m02:55:58
[2025-08-12T02:55:58.967+0000] {subprocess.py:93} INFO - [0m02:55:58    compiled code at target/compiled/transaction_analytics/models/marts/dim_cards.sql
[2025-08-12T02:55:58.968+0000] {subprocess.py:93} INFO - [0m02:55:58
[2025-08-12T02:55:58.970+0000] {subprocess.py:93} INFO - [0m02:55:58  Done. PASS=6 WARN=0 ERROR=1 SKIP=1 NO-OP=0 TOTAL=8
[2025-08-12T02:56:01.791+0000] {subprocess.py:97} INFO - Command exited with return code 1
[2025-08-12T02:56:01.806+0000] {taskinstance.py:441} INFO - ::group::Post task execution logs
[2025-08-12T02:56:01.827+0000] {taskinstance.py:2905} ERROR - Task failed with exception
Traceback (most recent call last):
  File "/home/airflow/.local/lib/python3.12/site-packages/airflow/models/taskinstance.py", line 465, in _execute_task
    result = _execute_callable(context=context, **execute_callable_kwargs)
             ^^^^^^^^^^^^^^^^^^^^^^^^^^^^^^^^^^^^^^^^^^^^^^^^^^^^^^^^^^^^^
  File "/home/airflow/.local/lib/python3.12/site-packages/airflow/models/taskinstance.py", line 432, in _execute_callable
    return execute_callable(context=context, **execute_callable_kwargs)
           ^^^^^^^^^^^^^^^^^^^^^^^^^^^^^^^^^^^^^^^^^^^^^^^^^^^^^^^^^^^^
  File "/home/airflow/.local/lib/python3.12/site-packages/airflow/models/baseoperator.py", line 401, in wrapper
    return func(self, *args, **kwargs)
           ^^^^^^^^^^^^^^^^^^^^^^^^^^^
  File "/home/airflow/.local/lib/python3.12/site-packages/airflow/operators/bash.py", line 243, in execute
    raise AirflowException(
airflow.exceptions.AirflowException: Bash command failed. The command returned a non-zero exit code 1.
[2025-08-12T02:56:01.836+0000] {taskinstance.py:1206} INFO - Marking task as FAILED. dag_id=dbt_run_pipeline_v1, task_id=dbt_run, run_id=manual__2025-08-12T02:55:26.877659+00:00, execution_date=20250812T025526, start_date=20250812T025529, end_date=20250812T025601
[2025-08-12T02:56:01.868+0000] {standard_task_runner.py:110} ERROR - Failed to execute job 14 for task dbt_run (Bash command failed. The command returned a non-zero exit code 1.; 1793)
[2025-08-12T02:56:01.914+0000] {local_task_job_runner.py:240} INFO - Task exited with return code 1
[2025-08-12T02:56:01.940+0000] {taskinstance.py:3503} INFO - 0 downstream tasks scheduled from follow-on schedule check
[2025-08-12T02:56:01.952+0000] {local_task_job_runner.py:222} INFO - ::endgroup::
