[2025-08-02T16:55:24.457+0000] {local_task_job_runner.py:120} INFO - ::group::Pre task execution logs
[2025-08-02T16:55:24.489+0000] {taskinstance.py:2076} INFO - Dependencies all met for dep_context=non-requeueable deps ti=<TaskInstance: gcs_extract_and_load_v1.load_transactions_csv_to_gcs manual__2025-08-02T16:55:13.577782+00:00 [queued]>
[2025-08-02T16:55:24.501+0000] {taskinstance.py:2076} INFO - Dependencies all met for dep_context=requeueable deps ti=<TaskInstance: gcs_extract_and_load_v1.load_transactions_csv_to_gcs manual__2025-08-02T16:55:13.577782+00:00 [queued]>
[2025-08-02T16:55:24.502+0000] {taskinstance.py:2306} INFO - Starting attempt 1 of 1
[2025-08-02T16:55:24.526+0000] {taskinstance.py:2330} INFO - Executing <Task(PythonOperator): load_transactions_csv_to_gcs> on 2025-08-02 16:55:13.577782+00:00
[2025-08-02T16:55:24.544+0000] {warnings.py:112} WARNING - /home/***/.local/lib/python3.12/site-packages/***/task/task_runner/standard_task_runner.py:61: DeprecationWarning: This process (pid=701) is multi-threaded, use of fork() may lead to deadlocks in the child.
  pid = os.fork()

[2025-08-02T16:55:24.548+0000] {standard_task_runner.py:63} INFO - Started process 716 to run task
[2025-08-02T16:55:24.547+0000] {standard_task_runner.py:90} INFO - Running: ['***', 'tasks', 'run', 'gcs_extract_and_load_v1', 'load_transactions_csv_to_gcs', 'manual__2025-08-02T16:55:13.577782+00:00', '--job-id', '5', '--raw', '--subdir', 'DAGS_FOLDER/gcs_load_dag.py', '--cfg-path', '/tmp/tmpvs5lrqrv']
[2025-08-02T16:55:24.550+0000] {standard_task_runner.py:91} INFO - Job 5: Subtask load_transactions_csv_to_gcs
[2025-08-02T16:55:24.659+0000] {task_command.py:426} INFO - Running <TaskInstance: gcs_extract_and_load_v1.load_transactions_csv_to_gcs manual__2025-08-02T16:55:13.577782+00:00 [running]> on host 98321bfe6108
[2025-08-02T16:55:24.837+0000] {taskinstance.py:2648} INFO - Exporting env vars: AIRFLOW_CTX_DAG_OWNER='***' AIRFLOW_CTX_DAG_ID='gcs_extract_and_load_v1' AIRFLOW_CTX_TASK_ID='load_transactions_csv_to_gcs' AIRFLOW_CTX_EXECUTION_DATE='2025-08-02T16:55:13.577782+00:00' AIRFLOW_CTX_TRY_NUMBER='1' AIRFLOW_CTX_DAG_RUN_ID='manual__2025-08-02T16:55:13.577782+00:00'
[2025-08-02T16:55:24.843+0000] {taskinstance.py:430} INFO - ::endgroup::
[2025-08-02T16:55:25.381+0000] {connection.py:274} WARNING - Connection schemes (type: google_cloud_platform) shall not contain '_' according to RFC3986.
[2025-08-02T16:55:25.384+0000] {base.py:84} INFO - Using connection ID 'google_cloud_default' for task execution.
[2025-08-02T16:55:25.402+0000] {taskinstance.py:441} INFO - ::group::Post task execution logs
[2025-08-02T16:55:25.420+0000] {taskinstance.py:2905} ERROR - Task failed with exception
Traceback (most recent call last):
  File "/home/airflow/.local/lib/python3.12/site-packages/airflow/models/taskinstance.py", line 465, in _execute_task
    result = _execute_callable(context=context, **execute_callable_kwargs)
             ^^^^^^^^^^^^^^^^^^^^^^^^^^^^^^^^^^^^^^^^^^^^^^^^^^^^^^^^^^^^^
  File "/home/airflow/.local/lib/python3.12/site-packages/airflow/models/taskinstance.py", line 432, in _execute_callable
    return execute_callable(context=context, **execute_callable_kwargs)
           ^^^^^^^^^^^^^^^^^^^^^^^^^^^^^^^^^^^^^^^^^^^^^^^^^^^^^^^^^^^^
  File "/home/airflow/.local/lib/python3.12/site-packages/airflow/models/baseoperator.py", line 401, in wrapper
    return func(self, *args, **kwargs)
           ^^^^^^^^^^^^^^^^^^^^^^^^^^^
  File "/home/airflow/.local/lib/python3.12/site-packages/airflow/operators/python.py", line 235, in execute
    return_value = self.execute_callable()
                   ^^^^^^^^^^^^^^^^^^^^^^^
  File "/home/airflow/.local/lib/python3.12/site-packages/airflow/operators/python.py", line 252, in execute_callable
    return self.python_callable(*self.op_args, **self.op_kwargs)
           ^^^^^^^^^^^^^^^^^^^^^^^^^^^^^^^^^^^^^^^^^^^^^^^^^^^^^
  File "/opt/airflow/dags/gcs_load_dag.py", line 26, in upload_csv_to_gcs
    gcs_hook.upload(
  File "/home/airflow/.local/lib/python3.12/site-packages/airflow/providers/google/cloud/hooks/gcs.py", line 528, in upload
    client = self.get_conn()
             ^^^^^^^^^^^^^^^
  File "/home/airflow/.local/lib/python3.12/site-packages/airflow/providers/google/cloud/hooks/gcs.py", line 173, in get_conn
    credentials=self.get_credentials(), client_info=CLIENT_INFO, project=self.project_id
                ^^^^^^^^^^^^^^^^^^^^^^
  File "/home/airflow/.local/lib/python3.12/site-packages/airflow/providers/google/common/hooks/base_google.py", line 332, in get_credentials
    credentials, _ = self.get_credentials_and_project_id()
                     ^^^^^^^^^^^^^^^^^^^^^^^^^^^^^^^^^^^^^
  File "/home/airflow/.local/lib/python3.12/site-packages/airflow/providers/google/common/hooks/base_google.py", line 308, in get_credentials_and_project_id
    credentials, project_id = get_credentials_and_project_id(
                              ^^^^^^^^^^^^^^^^^^^^^^^^^^^^^^^
  File "/home/airflow/.local/lib/python3.12/site-packages/airflow/providers/google/cloud/utils/credentials_provider.py", line 371, in get_credentials_and_project_id
    return _CredentialProvider(*args, **kwargs).get_credentials_and_project()
           ^^^^^^^^^^^^^^^^^^^^^^^^^^^^^^^^^^^^^^^^^^^^^^^^^^^^^^^^^^^^^^^^^^
  File "/home/airflow/.local/lib/python3.12/site-packages/airflow/providers/google/cloud/utils/credentials_provider.py", line 245, in get_credentials_and_project
    credentials, project_id = self._get_credentials_using_key_path()
                              ^^^^^^^^^^^^^^^^^^^^^^^^^^^^^^^^^^^^^^
  File "/home/airflow/.local/lib/python3.12/site-packages/airflow/providers/google/cloud/utils/credentials_provider.py", line 292, in _get_credentials_using_key_path
    raise AirflowException("Unrecognised extension for key file.")
airflow.exceptions.AirflowException: Unrecognised extension for key file.
[2025-08-02T16:55:25.433+0000] {taskinstance.py:1206} INFO - Marking task as FAILED. dag_id=gcs_extract_and_load_v1, task_id=load_transactions_csv_to_gcs, run_id=manual__2025-08-02T16:55:13.577782+00:00, execution_date=20250802T165513, start_date=20250802T165524, end_date=20250802T165525
[2025-08-02T16:55:25.455+0000] {standard_task_runner.py:110} ERROR - Failed to execute job 5 for task load_transactions_csv_to_gcs (Unrecognised extension for key file.; 716)
[2025-08-02T16:55:25.535+0000] {local_task_job_runner.py:240} INFO - Task exited with return code 1
[2025-08-02T16:55:25.555+0000] {local_task_job_runner.py:222} INFO - ::endgroup::
