[2025-08-13T23:53:41.220+0000] {local_task_job_runner.py:120} INFO - ::group::Pre task execution logs
[2025-08-13T23:53:41.250+0000] {taskinstance.py:2076} INFO - Dependencies all met for dep_context=non-requeueable deps ti=<TaskInstance: gcs_process_all_files_v1.move_transactions_file manual__2025-08-13T23:53:34.661368+00:00 [queued]>
[2025-08-13T23:53:41.262+0000] {taskinstance.py:2076} INFO - Dependencies all met for dep_context=requeueable deps ti=<TaskInstance: gcs_process_all_files_v1.move_transactions_file manual__2025-08-13T23:53:34.661368+00:00 [queued]>
[2025-08-13T23:53:41.263+0000] {taskinstance.py:2306} INFO - Starting attempt 1 of 1
[2025-08-13T23:53:41.285+0000] {taskinstance.py:2330} INFO - Executing <Task(GCSToGCSOperator): move_transactions_file> on 2025-08-13 23:53:34.661368+00:00
[2025-08-13T23:53:41.302+0000] {warnings.py:112} WARNING - /home/***/.local/lib/python3.12/site-packages/***/task/task_runner/standard_task_runner.py:61: DeprecationWarning: This process (pid=6047) is multi-threaded, use of fork() may lead to deadlocks in the child.
  pid = os.fork()

[2025-08-13T23:53:41.309+0000] {standard_task_runner.py:63} INFO - Started process 6056 to run task
[2025-08-13T23:53:41.310+0000] {standard_task_runner.py:90} INFO - Running: ['***', 'tasks', 'run', 'gcs_process_all_files_v1', 'move_transactions_file', 'manual__2025-08-13T23:53:34.661368+00:00', '--job-id', '22', '--raw', '--subdir', 'DAGS_FOLDER/gcs_load_dag v2.py', '--cfg-path', '/tmp/tmp9aqh5_7r']
[2025-08-13T23:53:41.316+0000] {standard_task_runner.py:91} INFO - Job 22: Subtask move_transactions_file
[2025-08-13T23:53:41.429+0000] {task_command.py:426} INFO - Running <TaskInstance: gcs_process_all_files_v1.move_transactions_file manual__2025-08-13T23:53:34.661368+00:00 [running]> on host ef2de7cf7633
[2025-08-13T23:53:41.594+0000] {taskinstance.py:2648} INFO - Exporting env vars: AIRFLOW_CTX_DAG_OWNER='***' AIRFLOW_CTX_DAG_ID='gcs_process_all_files_v1' AIRFLOW_CTX_TASK_ID='move_transactions_file' AIRFLOW_CTX_EXECUTION_DATE='2025-08-13T23:53:34.661368+00:00' AIRFLOW_CTX_TRY_NUMBER='1' AIRFLOW_CTX_DAG_RUN_ID='manual__2025-08-13T23:53:34.661368+00:00'
[2025-08-13T23:53:41.598+0000] {taskinstance.py:430} INFO - ::endgroup::
[2025-08-13T23:53:41.642+0000] {taskinstance.py:441} INFO - ::group::Post task execution logs
[2025-08-13T23:53:41.657+0000] {taskinstance.py:2905} ERROR - Task failed with exception
Traceback (most recent call last):
  File "/home/airflow/.local/lib/python3.12/site-packages/airflow/models/taskinstance.py", line 465, in _execute_task
    result = _execute_callable(context=context, **execute_callable_kwargs)
             ^^^^^^^^^^^^^^^^^^^^^^^^^^^^^^^^^^^^^^^^^^^^^^^^^^^^^^^^^^^^^
  File "/home/airflow/.local/lib/python3.12/site-packages/airflow/models/taskinstance.py", line 432, in _execute_callable
    return execute_callable(context=context, **execute_callable_kwargs)
           ^^^^^^^^^^^^^^^^^^^^^^^^^^^^^^^^^^^^^^^^^^^^^^^^^^^^^^^^^^^^
  File "/home/airflow/.local/lib/python3.12/site-packages/airflow/models/baseoperator.py", line 401, in wrapper
    return func(self, *args, **kwargs)
           ^^^^^^^^^^^^^^^^^^^^^^^^^^^
  File "/home/airflow/.local/lib/python3.12/site-packages/airflow/providers/google/cloud/transfers/gcs_to_gcs.py", line 239, in execute
    hook = GCSHook(
           ^^^^^^^^
  File "/home/airflow/.local/lib/python3.12/site-packages/airflow/providers/google/cloud/hooks/gcs.py", line 164, in __init__
    super().__init__(
  File "/home/airflow/.local/lib/python3.12/site-packages/airflow/providers/google/common/hooks/base_google.py", line 274, in __init__
    self.extras: dict = self.get_connection(self.gcp_conn_id).extra_dejson
                        ^^^^^^^^^^^^^^^^^^^^^^^^^^^^^^^^^^^^^
  File "/home/airflow/.local/lib/python3.12/site-packages/airflow/hooks/base.py", line 83, in get_connection
    conn = Connection.get_connection_from_secrets(conn_id)
           ^^^^^^^^^^^^^^^^^^^^^^^^^^^^^^^^^^^^^^^^^^^^^^^
  File "/home/airflow/.local/lib/python3.12/site-packages/airflow/models/connection.py", line 519, in get_connection_from_secrets
    raise AirflowNotFoundException(f"The conn_id `{conn_id}` isn't defined")
airflow.exceptions.AirflowNotFoundException: The conn_id `google_cloud_default` isn't defined
[2025-08-13T23:53:41.666+0000] {taskinstance.py:1206} INFO - Marking task as FAILED. dag_id=gcs_process_all_files_v1, task_id=move_transactions_file, run_id=manual__2025-08-13T23:53:34.661368+00:00, execution_date=20250813T235334, start_date=20250813T235341, end_date=20250813T235341
[2025-08-13T23:53:41.730+0000] {standard_task_runner.py:110} ERROR - Failed to execute job 22 for task move_transactions_file (The conn_id `google_cloud_default` isn't defined; 6056)
[2025-08-13T23:53:41.767+0000] {local_task_job_runner.py:240} INFO - Task exited with return code 1
[2025-08-13T23:53:41.798+0000] {taskinstance.py:3503} INFO - 0 downstream tasks scheduled from follow-on schedule check
[2025-08-13T23:53:41.803+0000] {local_task_job_runner.py:222} INFO - ::endgroup::
